Workbook
Name NewMatrix: #REF!
Name RiskAutoStopPercChange: 1.5
Name RiskCorrelationSheet: #REF!
Name RiskExcelReportsGoInNewWorkbook: TRUE
Name RiskExcelReportsToGenerate: 0
Name RiskGenerateExcelReportsAtEndOfSimulation: FALSE
Name RiskRealTimeResults: FALSE
Name RiskReportGraphFormat: 0
Name RiskResultsUpdateFreq: 100
Name RiskShowRiskWindowAtEndOfSimulation: FALSE
Name RiskStatFunctionsUpdateFreq: 1
Name RiskTemplateSheetName: "myTemplate"
Name RiskUpdateStatFunctions: TRUE
Name sss: #REF!

Sheet RiskRGStrategic Cnv 2R34C1
Z1: -7178233
J2: Bin | K2: Height | Z2: 49892664
J3: -7270758.4 | K3: 23.499545 | Z3: 14850692
J4: 1793246.8 | K4: 17.98322
J5: 10857252 | K5: 20.962036
J6: 19921257 | K6: 19.196812
J7: 28985262 | K7: 11.142977
J8: 38049268 | K8: 7.8331818
J9: 47113273 | K9: 4.9646927
J10: 56177278 | K10: 2.6478361
J11: 65241283 | K11: 1.2135915
J12: 74305288 | K12: 0.55163252
J13: 83369293 | K13: 0.33097951
A4001: -11802761 | B4001: 0
A4002: -11802761 | B4002: =$K$3 -> 23.499545
A4003: -2738755.8 | B4003: =$K$3 -> 23.499545
A4004: -2738755.8 | B4004: 0
A4005: -2738755.8 | B4005: =$K$4 -> 17.98322
A4006: 6325249.4 | B4006: =$K$4 -> 17.98322
A4007: 6325249.4 | B4007: 0
A4008: 6325249.4 | B4008: =$K$5 -> 20.962036
A4009: 15389255 | B4009: =$K$5 -> 20.962036
A4010: 15389255 | B4010: 0
A4011: 15389255 | B4011: =$K$6 -> 19.196812
A4012: 24453260 | B4012: =$K$6 -> 19.196812
A4013: 24453260 | B4013: 0
A4014: 24453260 | B4014: =$K$7 -> 11.142977
A4015: 33517265 | B4015: =$K$7 -> 11.142977
A4016: 33517265 | B4016: 0
A4017: 33517265 | B4017: =$K$8 -> 7.8331818
A4018: 42581270 | B4018: =$K$8 -> 7.8331818
A4019: 42581270 | B4019: 0
A4020: 42581270 | B4020: =$K$9 -> 4.9646927
A4021: 51645275 | B4021: =$K$9 -> 4.9646927
A4022: 51645275 | B4022: 0
A4023: 51645275 | B4023: =$K$10 -> 2.6478361
A4024: 60709280 | B4024: =$K$10 -> 2.6478361
A4025: 60709280 | B4025: 0
A4026: 60709280 | B4026: =$K$11 -> 1.2135915
A4027: 69773286 | B4027: =$K$11 -> 1.2135915
...

Sheet RiskRGStrategic Cnv 2R36C1
Z1: -8431302
J2: Bin | K2: Height | Z2: 16203147
J3: -9746729 | K3: 23.527151 | Z3: 1610989.8
J4: -5708841.1 | K4: 50.521462
J5: -1670953.2 | K5: 45.073069
J6: 2366934.7 | K6: 46.063686
J7: 6404822.6 | K7: 37.395788
J8: 10442710 | K8: 20.555301
J9: 14480598 | K9: 12.630365
J10: 18518486 | K10: 6.6866641
J11: 22556374 | K11: 3.4671591
J12: 26594262 | K12: 0.9906169
J13: 30632150 | K13: 0.74296267
A4001: -11765673 | B4001: 0
A4002: -11765673 | B4002: =$K$3 -> 23.527151
A4003: -7727785.1 | B4003: =$K$3 -> 23.527151
A4004: -7727785.1 | B4004: 0
A4005: -7727785.1 | B4005: =$K$4 -> 50.521462
A4006: -3689897.2 | B4006: =$K$4 -> 50.521462
A4007: -3689897.2 | B4007: 0
A4008: -3689897.2 | B4008: =$K$5 -> 45.073069
A4009: 347990.73 | B4009: =$K$5 -> 45.073069
A4010: 347990.73 | B4010: 0
A4011: 347990.73 | B4011: =$K$6 -> 46.063686
A4012: 4385878.6 | B4012: =$K$6 -> 46.063686
A4013: 4385878.6 | B4013: 0
A4014: 4385878.6 | B4014: =$K$7 -> 37.395788
A4015: 8423766.5 | B4015: =$K$7 -> 37.395788
A4016: 8423766.5 | B4016: 0
A4017: 8423766.5 | B4017: =$K$8 -> 20.555301
A4018: 12461654 | B4018: =$K$8 -> 20.555301
A4019: 12461654 | B4019: 0
A4020: 12461654 | B4020: =$K$9 -> 12.630365
A4021: 16499542 | B4021: =$K$9 -> 12.630365
A4022: 16499542 | B4022: 0
A4023: 16499542 | B4023: =$K$10 -> 6.6866641
A4024: 20537430 | B4024: =$K$10 -> 6.6866641
A4025: 20537430 | B4025: 0
A4026: 20537430 | B4026: =$K$11 -> 3.4671591
A4027: 24575318 | B4027: =$K$11 -> 3.4671591
...

Sheet RiskRGStrategic Cnv 2R35C1
Z1: -8436326
J2: Bin | K2: Height | Z2: 17082860
J3: -9348674.5 | K3: 34.17105 | Z3: 1783241.9
J4: -5046787.4 | K4: 43.236839
J5: -744900.27 | K5: 46.026313
J6: 3556986.8 | K6: 44.166664
J7: 7858873.9 | K7: 27.662279
J8: 12160761 | K8: 17.899122
J9: 16462648 | K9: 10.460526
J10: 20764535 | K10: 5.3464909
J11: 25066422 | K11: 2.0921051
J12: 29368309 | K12: 0.9298245
J13: 33670196 | K13: 0.46491225
A4001: -11499618 | B4001: 0
A4002: -11499618 | B4002: =$K$3 -> 34.17105
A4003: -7197730.9 | B4003: =$K$3 -> 34.17105
A4004: -7197730.9 | B4004: 0
A4005: -7197730.9 | B4005: =$K$4 -> 43.236839
A4006: -2895843.8 | B4006: =$K$4 -> 43.236839
A4007: -2895843.8 | B4007: 0
A4008: -2895843.8 | B4008: =$K$5 -> 46.026313
A4009: 1406043.3 | B4009: =$K$5 -> 46.026313
A4010: 1406043.3 | B4010: 0
A4011: 1406043.3 | B4011: =$K$6 -> 44.166664
A4012: 5707930.4 | B4012: =$K$6 -> 44.166664
A4013: 5707930.4 | B4013: 0
A4014: 5707930.4 | B4014: =$K$7 -> 27.662279
A4015: 10009817 | B4015: =$K$7 -> 27.662279
A4016: 10009817 | B4016: 0
A4017: 10009817 | B4017: =$K$8 -> 17.899122
A4018: 14311705 | B4018: =$K$8 -> 17.899122
A4019: 14311705 | B4019: 0
A4020: 14311705 | B4020: =$K$9 -> 10.460526
A4021: 18613592 | B4021: =$K$9 -> 10.460526
A4022: 18613592 | B4022: 0
A4023: 18613592 | B4023: =$K$10 -> 5.3464909
A4024: 22915479 | B4024: =$K$10 -> 5.3464909
A4025: 22915479 | B4025: 0
A4026: 22915479 | B4026: =$K$11 -> 2.0921051
A4027: 27217366 | B4027: =$K$11 -> 2.0921051
...

Sheet RiskRGSheet1R33C1
Z1: -9.8195572
J2: Bin | K2: Height | Z2: 33.753624
J3: -32.107706 | K3: 0.12095782 | Z3: 12.079498
J4: -23.840362 | K4: 0.84670474
J5: -15.573017 | K5: 3.6287346
J6: -7.3056722 | K6: 10.402373
J7: 0.96167252 | K7: 21.167619
J8: 9.2290173 | K8: 28.908919
J9: 17.496362 | K9: 27.336467
J10: 25.763707 | K10: 17.7808
J11: 34.031051 | K11: 7.8622583
J12: 42.298396 | K12: 2.2981986
J13: 50.565741 | K13: 0.6047891
A4001: -36.241379 | B4001: 0
A4002: -36.241379 | B4002: =$K$3 -> 0.12095782
A4003: -27.974034 | B4003: =$K$3 -> 0.12095782
A4004: -27.974034 | B4004: 0
A4005: -27.974034 | B4005: =$K$4 -> 0.84670474
A4006: -19.706689 | B4006: =$K$4 -> 0.84670474
A4007: -19.706689 | B4007: 0
A4008: -19.706689 | B4008: =$K$5 -> 3.6287346
A4009: -11.439345 | B4009: =$K$5 -> 3.6287346
A4010: -11.439345 | B4010: 0
A4011: -11.439345 | B4011: =$K$6 -> 10.402373
A4012: -3.1719998 | B4012: =$K$6 -> 10.402373
A4013: -3.1719998 | B4013: 0
A4014: -3.1719998 | B4014: =$K$7 -> 21.167619
A4015: 5.0953449 | B4015: =$K$7 -> 21.167619
A4016: 5.0953449 | B4016: 0
A4017: 5.0953449 | B4017: =$K$8 -> 28.908919
A4018: 13.36269 | B4018: =$K$8 -> 28.908919
A4019: 13.36269 | B4019: 0
A4020: 13.36269 | B4020: =$K$9 -> 27.336467
A4021: 21.630034 | B4021: =$K$9 -> 27.336467
A4022: 21.630034 | B4022: 0
A4023: 21.630034 | B4023: =$K$10 -> 17.7808
A4024: 29.897379 | B4024: =$K$10 -> 17.7808
A4025: 29.897379 | B4025: 0
A4026: 29.897379 | B4026: =$K$11 -> 7.8622583
A4027: 38.164724 | B4027: =$K$11 -> 7.8622583
...

Sheet RiskRGSheet1R33C6
Z1: 0.025266975
J2: Bin | K2: Height | Z2: 0.83968531
J3: -0.063320121 | K3: 0.29096488 | Z3: 0.41759672
J4: 0.063831773 | K4: 0.68462325
J5: 0.19098367 | K5: 1.1381861
J6: 0.31813556 | K6: 1.4890556
J7: 0.44528746 | K7: 1.5318445
J8: 0.57243935 | K8: 1.2494374
J9: 0.69959124 | K9: 0.80443231
J10: 0.82674314 | K10: 0.41077395
J11: 0.95389503 | K11: 0.1797136
J12: 1.0810469 | K12: 0.059904534
J13: 1.2081988 | K13: 0.025673372
A4001: -0.12689607 | B4001: 0
A4002: -0.12689607 | B4002: =$K$3 -> 0.29096488
A4003: 0.00025582584 | B4003: =$K$3 -> 0.29096488
A4004: 0.00025582584 | B4004: 0
A4005: 0.00025582584 | B4005: =$K$4 -> 0.68462325
A4006: 0.12740772 | B4006: =$K$4 -> 0.68462325
A4007: 0.12740772 | B4007: 0
A4008: 0.12740772 | B4008: =$K$5 -> 1.1381861
A4009: 0.25455961 | B4009: =$K$5 -> 1.1381861
A4010: 0.25455961 | B4010: 0
A4011: 0.25455961 | B4011: =$K$6 -> 1.4890556
A4012: 0.38171151 | B4012: =$K$6 -> 1.4890556
A4013: 0.38171151 | B4013: 0
A4014: 0.38171151 | B4014: =$K$7 -> 1.5318445
A4015: 0.5088634 | B4015: =$K$7 -> 1.5318445
A4016: 0.5088634 | B4016: 0
A4017: 0.5088634 | B4017: =$K$8 -> 1.2494374
A4018: 0.6360153 | B4018: =$K$8 -> 1.2494374
A4019: 0.6360153 | B4019: 0
A4020: 0.6360153 | B4020: =$K$9 -> 0.80443231
A4021: 0.76316719 | B4021: =$K$9 -> 0.80443231
A4022: 0.76316719 | B4022: 0
A4023: 0.76316719 | B4023: =$K$10 -> 0.41077395
A4024: 0.89031909 | B4024: =$K$10 -> 0.41077395
A4025: 0.89031909 | B4025: 0
A4026: 0.89031909 | B4026: =$K$11 -> 0.1797136
A4027: 1.017471 | B4027: =$K$11 -> 0.1797136
...

Sheet RiskRGSheet1R34C1
Z1: -9.7257814
J2: Bin | K2: Height | Z2: 33.840965
J3: -35.157652 | K3: 0.044888354 | Z3: 12.08197
J4: -27.731821 | K4: 0.40399518
J5: -20.305989 | K5: 1.5710924
J6: -12.880158 | K6: 5.2968257
J7: -5.4543272 | K7: 12.658516
J8: 1.9715039 | K8: 22.3544
J9: 9.3973351 | K9: 29.132541
J10: 16.823166 | K10: 27.965444
J11: 24.248997 | K11: 19.750876
J12: 31.674828 | K12: 10.234545
J13: 39.10066 | K13: 3.9052868
J14: 46.526491 | K14: 1.0773205
J15: 53.952322 | K15: 0.26933012
A4001: -38.870567 | B4001: 0
A4002: -38.870567 | B4002: =$K$3 -> 0.044888354
A4003: -31.444736 | B4003: =$K$3 -> 0.044888354
A4004: -31.444736 | B4004: 0
A4005: -31.444736 | B4005: =$K$4 -> 0.40399518
A4006: -24.018905 | B4006: =$K$4 -> 0.40399518
A4007: -24.018905 | B4007: 0
A4008: -24.018905 | B4008: =$K$5 -> 1.5710924
A4009: -16.593074 | B4009: =$K$5 -> 1.5710924
A4010: -16.593074 | B4010: 0
A4011: -16.593074 | B4011: =$K$6 -> 5.2968257
A4012: -9.1672428 | B4012: =$K$6 -> 5.2968257
A4013: -9.1672428 | B4013: 0
A4014: -9.1672428 | B4014: =$K$7 -> 12.658516
A4015: -1.7414116 | B4015: =$K$7 -> 12.658516
A4016: -1.7414116 | B4016: 0
A4017: -1.7414116 | B4017: =$K$8 -> 22.3544
A4018: 5.6844195 | B4018: =$K$8 -> 22.3544
A4019: 5.6844195 | B4019: 0
A4020: 5.6844195 | B4020: =$K$9 -> 29.132541
A4021: 13.110251 | B4021: =$K$9 -> 29.132541
A4022: 13.110251 | B4022: 0
A4023: 13.110251 | B4023: =$K$10 -> 27.965444
A4024: 20.536082 | B4024: =$K$10 -> 27.965444
A4025: 20.536082 | B4025: 0
...

Sheet RiskRGSheet1R34C6
Z1: 0.025207884
J2: Bin | K2: Height | Z2: 0.83929157
J3: -0.071324881 | K3: 0.26085056 | Z3: 0.41741707
J4: 0.041264902 | K4: 0.61831244
J5: 0.15385469 | K5: 1.0079781
J6: 0.26644447 | K6: 1.3751011
J7: 0.37903425 | K7: 1.561883
J8: 0.49162404 | K8: 1.4620513
J9: 0.60421382 | K9: 1.1335728
J10: 0.7168036 | K10: 0.74390715
J11: 0.82939339 | K11: 0.40898792
J12: 0.94198317 | K12: 0.19000226
J13: 1.054573 | K13: 0.080509432
J14: 1.1671627 | K14: 0.025763018
J15: 1.2797525 | K15: 0.012881509
A4001: -0.12761977 | B4001: 0
A4002: -0.12761977 | B4002: =$K$3 -> 0.26085056
A4003: -0.01502999 | B4003: =$K$3 -> 0.26085056
A4004: -0.01502999 | B4004: 0
A4005: -0.01502999 | B4005: =$K$4 -> 0.61831244
A4006: 0.097559794 | B4006: =$K$4 -> 0.61831244
A4007: 0.097559794 | B4007: 0
A4008: 0.097559794 | B4008: =$K$5 -> 1.0079781
A4009: 0.21014958 | B4009: =$K$5 -> 1.0079781
A4010: 0.21014958 | B4010: 0
A4011: 0.21014958 | B4011: =$K$6 -> 1.3751011
A4012: 0.32273936 | B4012: =$K$6 -> 1.3751011
A4013: 0.32273936 | B4013: 0
A4014: 0.32273936 | B4014: =$K$7 -> 1.561883
A4015: 0.43532914 | B4015: =$K$7 -> 1.561883
A4016: 0.43532914 | B4016: 0
A4017: 0.43532914 | B4017: =$K$8 -> 1.4620513
A4018: 0.54791893 | B4018: =$K$8 -> 1.4620513
A4019: 0.54791893 | B4019: 0
A4020: 0.54791893 | B4020: =$K$9 -> 1.1335728
A4021: 0.66050871 | B4021: =$K$9 -> 1.1335728
A4022: 0.66050871 | B4022: 0
A4023: 0.66050871 | B4023: =$K$10 -> 0.74390715
A4024: 0.77309849 | B4024: =$K$10 -> 0.74390715
A4025: 0.77309849 | B4025: 0
...

Sheet RiskRGStatic ModetatsR34C1
Z1: -9.7421331
J2: Bin | K2: Height | Z2: 33.638954
J3: -26.789779 | K3: 0.49162835 | Z3: 12.079677
J4: -18.653552 | K4: 2.2123276
J5: -10.517325 | K5: 7.1286111
J6: -2.3810977 | K6: 16.715364
J7: 5.7551295 | K7: 26.547931
J8: 13.891357 | K8: 29.251887
J9: 22.027584 | K9: 22.860718
J10: 30.163811 | K10: 12.044895
J11: 38.300038 | K11: 4.4246552
J12: 46.436266 | K12: 1.2290709
A4001: -30.857893 | B4001: 0
A4002: -30.857893 | B4002: =$K$3 -> 0.49162835
A4003: -22.721666 | B4003: =$K$3 -> 0.49162835
A4004: -22.721666 | B4004: 0
A4005: -22.721666 | B4005: =$K$4 -> 2.2123276
A4006: -14.585439 | B4006: =$K$4 -> 2.2123276
A4007: -14.585439 | B4007: 0
A4008: -14.585439 | B4008: =$K$5 -> 7.1286111
A4009: -6.4492113 | B4009: =$K$5 -> 7.1286111
A4010: -6.4492113 | B4010: 0
A4011: -6.4492113 | B4011: =$K$6 -> 16.715364
A4012: 1.6870159 | B4012: =$K$6 -> 16.715364
A4013: 1.6870159 | B4013: 0
A4014: 1.6870159 | B4014: =$K$7 -> 26.547931
A4015: 9.8232431 | B4015: =$K$7 -> 26.547931
A4016: 9.8232431 | B4016: 0
A4017: 9.8232431 | B4017: =$K$8 -> 29.251887
A4018: 17.95947 | B4018: =$K$8 -> 29.251887
A4019: 17.95947 | B4019: 0
A4020: 17.95947 | B4020: =$K$9 -> 22.860718
A4021: 26.095698 | B4021: =$K$9 -> 22.860718
A4022: 26.095698 | B4022: 0
A4023: 26.095698 | B4023: =$K$10 -> 12.044895
A4024: 34.231925 | B4024: =$K$10 -> 12.044895
A4025: 34.231925 | B4025: 0
A4026: 34.231925 | B4026: =$K$11 -> 4.4246552
A4027: 42.368152 | B4027: =$K$11 -> 4.4246552
A4028: 42.368152 | B4028: 0
...

Sheet RiskRGStatic ModetatsR34C6
Z1: 0.02375216
J2: Bin | K2: Height | Z2: 0.83634168
J3: -0.028522137 | K3: 0.44382338 | Z3: 0.41703365
J4: 0.098829737 | K4: 0.81936624
J5: 0.22618161 | K5: 1.2461195
J6: 0.35353349 | K6: 1.5363117
J7: 0.48088536 | K7: 1.4680312
J8: 0.60823723 | K8: 1.1266286
J9: 0.73558911 | K9: 0.6828052
J10: 0.86294098 | K10: 0.3414026
J11: 0.99029286 | K11: 0.11949091
J12: 1.1176447 | K12: 0.06828052
A4001: -0.092198074 | B4001: 0
A4002: -0.092198074 | B4002: =$K$3 -> 0.44382338
A4003: 0.0351538 | B4003: =$K$3 -> 0.44382338
A4004: 0.0351538 | B4004: 0
A4005: 0.0351538 | B4005: =$K$4 -> 0.81936624
A4006: 0.16250567 | B4006: =$K$4 -> 0.81936624
A4007: 0.16250567 | B4007: 0
A4008: 0.16250567 | B4008: =$K$5 -> 1.2461195
A4009: 0.28985755 | B4009: =$K$5 -> 1.2461195
A4010: 0.28985755 | B4010: 0
A4011: 0.28985755 | B4011: =$K$6 -> 1.5363117
A4012: 0.41720942 | B4012: =$K$6 -> 1.5363117
A4013: 0.41720942 | B4013: 0
A4014: 0.41720942 | B4014: =$K$7 -> 1.4680312
A4015: 0.5445613 | B4015: =$K$7 -> 1.4680312
A4016: 0.5445613 | B4016: 0
A4017: 0.5445613 | B4017: =$K$8 -> 1.1266286
A4018: 0.67191317 | B4018: =$K$8 -> 1.1266286
A4019: 0.67191317 | B4019: 0
A4020: 0.67191317 | B4020: =$K$9 -> 0.6828052
A4021: 0.79926504 | B4021: =$K$9 -> 0.6828052
A4022: 0.79926504 | B4022: 0
A4023: 0.79926504 | B4023: =$K$10 -> 0.3414026
A4024: 0.92661692 | B4024: =$K$10 -> 0.3414026
A4025: 0.92661692 | B4025: 0
A4026: 0.92661692 | B4026: =$K$11 -> 0.11949091
A4027: 1.0539688 | B4027: =$K$11 -> 0.11949091
A4028: 1.0539688 | B4028: 0
...

Sheet RiskRGStrategic Cnv 2R32C1
Z1: -5226611
J2: Bin | K2: Height | Z2: 35739460
J3: -3521957.6 | K3: 26.760044 | Z3: 13035168
J4: 3055012.3 | K4: 23.71913
J5: 9631982.1 | K5: 29.496866
J6: 16208952 | K6: 27.368226
J7: 22785922 | K7: 20.070033
J8: 29362892 | K8: 13.07593
J9: 35939862 | K9: 6.9941023
J10: 42516831 | K10: 3.040914
J11: 49093801 | K11: 1.2163656
J12: 55670771 | K12: 0.3040914
A4001: -6810442.5 | B4001: 0
A4002: -6810442.5 | B4002: =$K$3 -> 26.760044
A4003: -233472.65 | B4003: =$K$3 -> 26.760044
A4004: -233472.65 | B4004: 0
A4005: -233472.65 | B4005: =$K$4 -> 23.71913
A4006: 6343497.2 | B4006: =$K$4 -> 23.71913
A4007: 6343497.2 | B4007: 0
A4008: 6343497.2 | B4008: =$K$5 -> 29.496866
A4009: 12920467 | B4009: =$K$5 -> 29.496866
A4010: 12920467 | B4010: 0
A4011: 12920467 | B4011: =$K$6 -> 27.368226
A4012: 19497437 | B4012: =$K$6 -> 27.368226
A4013: 19497437 | B4013: 0
A4014: 19497437 | B4014: =$K$7 -> 20.070033
A4015: 26074407 | B4015: =$K$7 -> 20.070033
A4016: 26074407 | B4016: 0
A4017: 26074407 | B4017: =$K$8 -> 13.07593
A4018: 32651377 | B4018: =$K$8 -> 13.07593
A4019: 32651377 | B4019: 0
A4020: 32651377 | B4020: =$K$9 -> 6.9941023
A4021: 39228346 | B4021: =$K$9 -> 6.9941023
A4022: 39228346 | B4022: 0
A4023: 39228346 | B4023: =$K$10 -> 3.040914
A4024: 45805316 | B4024: =$K$10 -> 3.040914
A4025: 45805316 | B4025: 0
A4026: 45805316 | B4026: =$K$11 -> 1.2163656
A4027: 52382286 | B4027: =$K$11 -> 1.2163656
A4028: 52382286 | B4028: 0
...

Sheet RiskRGStrategic Cnv 2R42C1
Z1: -5.2143726
J2: Bin | K2: Height | Z2: 35.776337
J3: -3.2817166 | K3: 26.355118 | Z3: 13.044224
J4: 3.7757361 | K4: 24.3714
J5: 10.833189 | K5: 30.039167
J6: 17.890641 | K6: 25.221565
J7: 24.948094 | K7: 17.853467
J8: 32.005547 | K8: 10.48537
J9: 39.062999 | K9: 4.8176023
J10: 46.120452 | K10: 1.9837186
J11: 53.177905 | K11: 0.28338837
J12: 60.235358 | K12: 0.28338837
A4001: -6.8104429 | B4001: 0
A4002: -6.8104429 | B4002: =$K$3 -> 26.355118
A4003: 0.24700975 | B4003: =$K$3 -> 26.355118
A4004: 0.24700975 | B4004: 0
A4005: 0.24700975 | B4005: =$K$4 -> 24.3714
A4006: 7.3044624 | B4006: =$K$4 -> 24.3714
A4007: 7.3044624 | B4007: 0
A4008: 7.3044624 | B4008: =$K$5 -> 30.039167
A4009: 14.361915 | B4009: =$K$5 -> 30.039167
A4010: 14.361915 | B4010: 0
A4011: 14.361915 | B4011: =$K$6 -> 25.221565
A4012: 21.419368 | B4012: =$K$6 -> 25.221565
A4013: 21.419368 | B4013: 0
A4014: 21.419368 | B4014: =$K$7 -> 17.853467
A4015: 28.47682 | B4015: =$K$7 -> 17.853467
A4016: 28.47682 | B4016: 0
A4017: 28.47682 | B4017: =$K$8 -> 10.48537
A4018: 35.534273 | B4018: =$K$8 -> 10.48537
A4019: 35.534273 | B4019: 0
A4020: 35.534273 | B4020: =$K$9 -> 4.8176023
A4021: 42.591726 | B4021: =$K$9 -> 4.8176023
A4022: 42.591726 | B4022: 0
A4023: 42.591726 | B4023: =$K$10 -> 1.9837186
A4024: 49.649179 | B4024: =$K$10 -> 1.9837186
A4025: 49.649179 | B4025: 0
A4026: 49.649179 | B4026: =$K$11 -> 0.28338837
A4027: 56.706631 | B4027: =$K$11 -> 0.28338837
A4028: 56.706631 | B4028: 0
...

Sheet RiskRGStrategic Cnv 2R39C1
Z1: 0.089532284
J2: Bin | K2: Height | Z2: 0.79585623
J3: 0.062396155 | K3: 0.60037534 | Z3: 0.43823032
J4: 0.18136935 | K4: 0.99437165
J5: 0.30034254 | K5: 1.388368
J6: 0.41931574 | K6: 1.5572235
J7: 0.53828893 | K7: 2.2138841
J8: 0.65726212 | K8: 0.88180128
J9: 0.77623532 | K9: 0.4502815
J10: 0.89520851 | K10: 0.22514075
J11: 1.0141817 | K11: 0.056285188
J12: 1.1331549 | K12: 0.037523459
A4001: 0.0029095581 | B4001: 0
A4002: 0.0029095581 | B4002: =$K$3 -> 0.60037534
A4003: 0.12188275 | B4003: =$K$3 -> 0.60037534
A4004: 0.12188275 | B4004: 0
A4005: 0.12188275 | B4005: =$K$4 -> 0.99437165
A4006: 0.24085595 | B4006: =$K$4 -> 0.99437165
A4007: 0.24085595 | B4007: 0
A4008: 0.24085595 | B4008: =$K$5 -> 1.388368
A4009: 0.35982914 | B4009: =$K$5 -> 1.388368
A4010: 0.35982914 | B4010: 0
A4011: 0.35982914 | B4011: =$K$6 -> 1.5572235
A4012: 0.47880233 | B4012: =$K$6 -> 1.5572235
A4013: 0.47880233 | B4013: 0
A4014: 0.47880233 | B4014: =$K$7 -> 2.2138841
A4015: 0.59777553 | B4015: =$K$7 -> 2.2138841
A4016: 0.59777553 | B4016: 0
A4017: 0.59777553 | B4017: =$K$8 -> 0.88180128
A4018: 0.71674872 | B4018: =$K$8 -> 0.88180128
A4019: 0.71674872 | B4019: 0
A4020: 0.71674872 | B4020: =$K$9 -> 0.4502815
A4021: 0.83572192 | B4021: =$K$9 -> 0.4502815
A4022: 0.83572192 | B4022: 0
A4023: 0.83572192 | B4023: =$K$10 -> 0.22514075
A4024: 0.95469511 | B4024: =$K$10 -> 0.22514075
A4025: 0.95469511 | B4025: 0
A4026: 0.95469511 | B4026: =$K$11 -> 0.056285188
A4027: 1.0736683 | B4027: =$K$11 -> 0.056285188
A4028: 1.0736683 | B4028: 0
...

Sheet RiskRGStrategic Cnv 2R39C6
Z1: -5.2089324
J2: Bin | K2: Height | Z2: 35.545898
J3: -3.4842251 | K3: 27.464109 | Z3: 13.033911
J4: 2.9241385 | K4: 23.406911
J5: 9.3325021 | K5: 29.336662
J6: 15.740866 | K6: 27.776202
J7: 22.149229 | K7: 20.598082
J8: 28.557593 | K8: 14.356239
J9: 34.965957 | K9: 7.8023038
J10: 41.37432 | K10: 3.4330137
J11: 47.782684 | K11: 1.2483686
J12: 54.191048 | K12: 0.62418431
A4001: -6.6884069 | B4001: 0
A4002: -6.6884069 | B4002: =$K$3 -> 27.464109
A4003: -0.28004332 | B4003: =$K$3 -> 27.464109
A4004: -0.28004332 | B4004: 0
A4005: -0.28004332 | B4005: =$K$4 -> 23.406911
A4006: 6.1283203 | B4006: =$K$4 -> 23.406911
A4007: 6.1283203 | B4007: 0
A4008: 6.1283203 | B4008: =$K$5 -> 29.336662
A4009: 12.536684 | B4009: =$K$5 -> 29.336662
A4010: 12.536684 | B4010: 0
A4011: 12.536684 | B4011: =$K$6 -> 27.776202
A4012: 18.945048 | B4012: =$K$6 -> 27.776202
A4013: 18.945048 | B4013: 0
A4014: 18.945048 | B4014: =$K$7 -> 20.598082
A4015: 25.353411 | B4015: =$K$7 -> 20.598082
A4016: 25.353411 | B4016: 0
A4017: 25.353411 | B4017: =$K$8 -> 14.356239
A4018: 31.761775 | B4018: =$K$8 -> 14.356239
A4019: 31.761775 | B4019: 0
A4020: 31.761775 | B4020: =$K$9 -> 7.8023038
A4021: 38.170138 | B4021: =$K$9 -> 7.8023038
A4022: 38.170138 | B4022: 0
A4023: 38.170138 | B4023: =$K$10 -> 3.4330137
A4024: 44.578502 | B4024: =$K$10 -> 3.4330137
A4025: 44.578502 | B4025: 0
A4026: 44.578502 | B4026: =$K$11 -> 1.2483686
A4027: 50.986866 | B4027: =$K$11 -> 1.2483686
A4028: 50.986866 | B4028: 0
...

Sheet RiskRGStatic ModetatsR51C1
Z1: -2481422.8
J2: Bin | K2: Height | Z2: 1932187.6
J3: -3760525.1 | K3: 14.127506 | Z3: -260379.22
J4: -2911118.3 | K4: 42.382519
J5: -2061711.5 | K5: 122.43839
J6: -1212304.7 | K6: 230.74927
J7: -362897.9 | K7: 291.96847
J8: 486508.9 | K8: 249.58595
J9: 1335915.7 | K9: 148.33882
J10: 2185322.5 | K10: 58.86461
J11: 3034729.3 | K11: 16.482091
J12: 3884136.1 | K12: 2.3545844
A4001: -4185228.5 | B4001: 0
A4002: -4185228.5 | B4002: =$K$3 -> 14.127506
A4003: -3335821.7 | B4003: =$K$3 -> 14.127506
A4004: -3335821.7 | B4004: 0
A4005: -3335821.7 | B4005: =$K$4 -> 42.382519
A4006: -2486414.9 | B4006: =$K$4 -> 42.382519
A4007: -2486414.9 | B4007: 0
A4008: -2486414.9 | B4008: =$K$5 -> 122.43839
A4009: -1637008.1 | B4009: =$K$5 -> 122.43839
A4010: -1637008.1 | B4010: 0
A4011: -1637008.1 | B4011: =$K$6 -> 230.74927
A4012: -787601.3 | B4012: =$K$6 -> 230.74927
A4013: -787601.3 | B4013: 0
A4014: -787601.3 | B4014: =$K$7 -> 291.96847
A4015: 61805.5 | B4015: =$K$7 -> 291.96847
A4016: 61805.5 | B4016: 0
A4017: 61805.5 | B4017: =$K$8 -> 249.58595
A4018: 911212.3 | B4018: =$K$8 -> 249.58595
A4019: 911212.3 | B4019: 0
A4020: 911212.3 | B4020: =$K$9 -> 148.33882
A4021: 1760619.1 | B4021: =$K$9 -> 148.33882
A4022: 1760619.1 | B4022: 0
A4023: 1760619.1 | B4023: =$K$10 -> 58.86461
A4024: 2610025.9 | B4024: =$K$10 -> 58.86461
A4025: 2610025.9 | B4025: 0
A4026: 2610025.9 | B4026: =$K$11 -> 16.482091
A4027: 3459432.7 | B4027: =$K$11 -> 16.482091
A4028: 3459432.7 | B4028: 0
...

Sheet RiskRGStatic ModetatsR51C6
Z1: -2111418.8
J2: Bin | K2: Height | Z2: 3469036.2
J3: -3728683 | K3: 11.173516 | Z3: 696811.37
J4: -2654714.9 | K4: 33.520549
J5: -1580746.8 | K5: 96.837141
J6: -506778.65 | K6: 182.50077
J7: 567189.45 | K7: 230.91934
J8: 1641157.6 | K8: 197.39879
J9: 2715125.6 | K9: 117.32192
J10: 3789093.8 | K10: 46.556318
J11: 4863061.8 | K11: 13.035769
J12: 5937030 | K12: 1.8622527
A4001: -4265667 | B4001: 0
A4002: -4265667 | B4002: =$K$3 -> 11.173516
A4003: -3191698.9 | B4003: =$K$3 -> 11.173516
A4004: -3191698.9 | B4004: 0
A4005: -3191698.9 | B4005: =$K$4 -> 33.520549
A4006: -2117730.8 | B4006: =$K$4 -> 33.520549
A4007: -2117730.8 | B4007: 0
A4008: -2117730.8 | B4008: =$K$5 -> 96.837141
A4009: -1043762.7 | B4009: =$K$5 -> 96.837141
A4010: -1043762.7 | B4010: 0
A4011: -1043762.7 | B4011: =$K$6 -> 182.50077
A4012: 30205.4 | B4012: =$K$6 -> 182.50077
A4013: 30205.4 | B4013: 0
A4014: 30205.4 | B4014: =$K$7 -> 230.91934
A4015: 1104173.5 | B4015: =$K$7 -> 230.91934
A4016: 1104173.5 | B4016: 0
A4017: 1104173.5 | B4017: =$K$8 -> 197.39879
A4018: 2178141.6 | B4018: =$K$8 -> 197.39879
A4019: 2178141.6 | B4019: 0
A4020: 2178141.6 | B4020: =$K$9 -> 117.32192
A4021: 3252109.7 | B4021: =$K$9 -> 117.32192
A4022: 3252109.7 | B4022: 0
A4023: 3252109.7 | B4023: =$K$10 -> 46.556318
A4024: 4326077.8 | B4024: =$K$10 -> 46.556318
A4025: 4326077.8 | B4025: 0
A4026: 4326077.8 | B4026: =$K$11 -> 13.035769
A4027: 5400045.9 | B4027: =$K$11 -> 13.035769
A4028: 5400045.9 | B4028: 0
...

Sheet RiskRGSCI DynamicodelR65C6
Z1: -1808508.9
J2: Bin | K2: Height | Z2: 1650000
J3: -1806303.2 | K3: 193.82329 | Z3: -19847.59
J4: -1311006.7 | K4: 246.31709
J5: -815710.19 | K5: 270.545
J6: -320413.66 | K6: 274.58299
J7: 174882.86 | K7: 266.50702
J8: 670179.39 | K8: 262.46903
J9: 1165475.9 | K9: 238.24112
J10: 1660772.4 | K10: 262.46903
J11: 2156069 | K11: 0
J12: 2651365.5 | K12: 4.0379851
A4001: -2053951.5 | B4001: 0
A4002: -2053951.5 | B4002: =$K$3 -> 193.82329
A4003: -1558655 | B4003: =$K$3 -> 193.82329
A4004: -1558655 | B4004: 0
A4005: -1558655 | B4005: =$K$4 -> 246.31709
A4006: -1063358.4 | B4006: =$K$4 -> 246.31709
A4007: -1063358.4 | B4007: 0
A4008: -1063358.4 | B4008: =$K$5 -> 270.545
A4009: -568061.93 | B4009: =$K$5 -> 270.545
A4010: -568061.93 | B4010: 0
A4011: -568061.93 | B4011: =$K$6 -> 274.58299
A4012: -72765.4 | B4012: =$K$6 -> 274.58299
A4013: -72765.4 | B4013: 0
A4014: -72765.4 | B4014: =$K$7 -> 266.50702
A4015: 422531.12 | B4015: =$K$7 -> 266.50702
A4016: 422531.12 | B4016: 0
A4017: 422531.12 | B4017: =$K$8 -> 262.46903
A4018: 917827.65 | B4018: =$K$8 -> 262.46903
A4019: 917827.65 | B4019: 0
A4020: 917827.65 | B4020: =$K$9 -> 238.24112
A4021: 1413124.2 | B4021: =$K$9 -> 238.24112
A4022: 1413124.2 | B4022: 0
A4023: 1413124.2 | B4023: =$K$10 -> 262.46903
A4024: 1908420.7 | B4024: =$K$10 -> 262.46903
A4025: 1908420.7 | B4025: 0
A4026: 1908420.7 | B4026: =$K$11 -> 0
A4027: 2403717.2 | B4027: =$K$11 -> 0
A4028: 2403717.2 | B4028: 0
...

Sheet RiskRGStatic ModetatsR33C1
Z1: -8.6462927
J2: Bin | K2: Height | Z2: 37.748196
J3: -27.397892 | K3: 0.48414215 | Z3: 14.631968
J4: -19.135855 | K4: 1.6944975
J5: -10.873819 | K5: 5.5676347
J6: -2.6117829 | K6: 13.55598
J7: 5.6502534 | K7: 22.875717
J8: 13.91229 | K8: 27.838174
J9: 22.174326 | K9: 24.328143
J10: 30.436362 | K10: 15.129442
J11: 38.698398 | K11: 6.7779901
J12: 46.960435 | K12: 2.2996752
J13: 55.222471 | K13: 0.48414215
A4001: -31.52891 | B4001: 0
A4002: -31.52891 | B4002: =$K$3 -> 0.48414215
A4003: -23.266873 | B4003: =$K$3 -> 0.48414215
A4004: -23.266873 | B4004: 0
A4005: -23.266873 | B4005: =$K$4 -> 1.6944975
A4006: -15.004837 | B4006: =$K$4 -> 1.6944975
A4007: -15.004837 | B4007: 0
A4008: -15.004837 | B4008: =$K$5 -> 5.5676347
A4009: -6.742801 | B4009: =$K$5 -> 5.5676347
A4010: -6.742801 | B4010: 0
A4011: -6.742801 | B4011: =$K$6 -> 13.55598
A4012: 1.5192353 | B4012: =$K$6 -> 13.55598
A4013: 1.5192353 | B4013: 0
A4014: 1.5192353 | B4014: =$K$7 -> 22.875717
A4015: 9.7812715 | B4015: =$K$7 -> 22.875717
A4016: 9.7812715 | B4016: 0
A4017: 9.7812715 | B4017: =$K$8 -> 27.838174
A4018: 18.043308 | B4018: =$K$8 -> 27.838174
A4019: 18.043308 | B4019: 0
A4020: 18.043308 | B4020: =$K$9 -> 24.328143
A4021: 26.305344 | B4021: =$K$9 -> 24.328143
A4022: 26.305344 | B4022: 0
A4023: 26.305344 | B4023: =$K$10 -> 15.129442
A4024: 34.56738 | B4024: =$K$10 -> 15.129442
A4025: 34.56738 | B4025: 0
A4026: 34.56738 | B4026: =$K$11 -> 6.7779901
A4027: 42.829416 | B4027: =$K$11 -> 6.7779901
...

Sheet RiskRGStatic ModetatsR33C6
Z1: 0.063053714
J2: Bin | K2: Height | Z2: 0.96671053
J3: -0.050290857 | K3: 0.22684741 | Z3: 0.50226041
J4: 0.090848404 | K4: 0.54443378
J5: 0.23198766 | K5: 0.9603207
J6: 0.37312693 | K6: 1.3081534
J7: 0.51426619 | K7: 1.4064539
J8: 0.65540545 | K8: 1.1796065
J9: 0.79654471 | K9: 0.77884277
J10: 0.93768397 | K10: 0.40832534
J11: 1.0788232 | K11: 0.18147793
J12: 1.2199625 | K12: 0.068054223
J13: 1.3611018 | K13: 0.022684741
A4001: -0.12086049 | B4001: 0
A4002: -0.12086049 | B4002: =$K$3 -> 0.22684741
A4003: 0.020278774 | B4003: =$K$3 -> 0.22684741
A4004: 0.020278774 | B4004: 0
A4005: 0.020278774 | B4005: =$K$4 -> 0.54443378
A4006: 0.16141803 | B4006: =$K$4 -> 0.54443378
A4007: 0.16141803 | B4007: 0
A4008: 0.16141803 | B4008: =$K$5 -> 0.9603207
A4009: 0.3025573 | B4009: =$K$5 -> 0.9603207
A4010: 0.3025573 | B4010: 0
A4011: 0.3025573 | B4011: =$K$6 -> 1.3081534
A4012: 0.44369656 | B4012: =$K$6 -> 1.3081534
A4013: 0.44369656 | B4013: 0
A4014: 0.44369656 | B4014: =$K$7 -> 1.4064539
A4015: 0.58483582 | B4015: =$K$7 -> 1.4064539
A4016: 0.58483582 | B4016: 0
A4017: 0.58483582 | B4017: =$K$8 -> 1.1796065
A4018: 0.72597508 | B4018: =$K$8 -> 1.1796065
A4019: 0.72597508 | B4019: 0
A4020: 0.72597508 | B4020: =$K$9 -> 0.77884277
A4021: 0.86711434 | B4021: =$K$9 -> 0.77884277
A4022: 0.86711434 | B4022: 0
A4023: 0.86711434 | B4023: =$K$10 -> 0.40832534
A4024: 1.0082536 | B4024: =$K$10 -> 0.40832534
A4025: 1.0082536 | B4025: 0
A4026: 1.0082536 | B4026: =$K$11 -> 0.18147793
A4027: 1.1493929 | B4027: =$K$11 -> 0.18147793
...

Sheet RiskRGSCI DynamicodelR39C1
Z1: 0.10678878
J2: Bin | K2: Height | Z2: 0.87569126
J3: 0.062042684 | K3: 0.49150896 | Z3: 0.48029152
J4: 0.18224591 | K4: 0.82828363
J5: 0.30244913 | K5: 1.1832623
J6: 0.42265236 | K6: 1.4563229
J7: 0.54285559 | K7: 2.2117903
J8: 0.66305881 | K8: 1.010324
J9: 0.78326204 | K9: 0.6098352
J10: 0.90346526 | K10: 0.30946861
J11: 1.0236685 | K11: 0.13653027
J12: 1.1438717 | K12: 0.054612107
J13: 1.2640749 | K13: 0.027306054
A4001: 0.0019410715 | B4001: 0
A4002: 0.0019410715 | B4002: =$K$3 -> 0.49150896
A4003: 0.1221443 | B4003: =$K$3 -> 0.49150896
A4004: 0.1221443 | B4004: 0
A4005: 0.1221443 | B4005: =$K$4 -> 0.82828363
A4006: 0.24234752 | B4006: =$K$4 -> 0.82828363
A4007: 0.24234752 | B4007: 0
A4008: 0.24234752 | B4008: =$K$5 -> 1.1832623
A4009: 0.36255075 | B4009: =$K$5 -> 1.1832623
A4010: 0.36255075 | B4010: 0
A4011: 0.36255075 | B4011: =$K$6 -> 1.4563229
A4012: 0.48275397 | B4012: =$K$6 -> 1.4563229
A4013: 0.48275397 | B4013: 0
A4014: 0.48275397 | B4014: =$K$7 -> 2.2117903
A4015: 0.6029572 | B4015: =$K$7 -> 2.2117903
A4016: 0.6029572 | B4016: 0
A4017: 0.6029572 | B4017: =$K$8 -> 1.010324
A4018: 0.72316042 | B4018: =$K$8 -> 1.010324
A4019: 0.72316042 | B4019: 0
A4020: 0.72316042 | B4020: =$K$9 -> 0.6098352
A4021: 0.84336365 | B4021: =$K$9 -> 0.6098352
A4022: 0.84336365 | B4022: 0
A4023: 0.84336365 | B4023: =$K$10 -> 0.30946861
A4024: 0.96356687 | B4024: =$K$10 -> 0.30946861
A4025: 0.96356687 | B4025: 0
A4026: 0.96356687 | B4026: =$K$11 -> 0.13653027
A4027: 1.0837701 | B4027: =$K$11 -> 0.13653027
...

Sheet RiskRGSCI DynamicodelR39C6
Z1: -5.1260891
J2: Bin | K2: Height | Z2: 40.155487
J3: -3.5989465 | K3: 22.141753 | Z3: 15.655104
J4: 2.8594399 | K4: 19.974029
J5: 9.3178264 | K5: 26.167527
J6: 15.776213 | K6: 26.941714
J7: 22.234599 | K7: 22.296591
J8: 28.692986 | K8: 16.877281
J9: 35.151372 | K9: 10.683783
J10: 41.609759 | K10: 5.7289851
J11: 48.068145 | K11: 2.6322364
J12: 54.526532 | K12: 0.92902462
J13: 60.984918 | K13: 0.46451231
A4001: -6.8281398 | B4001: 0
A4002: -6.8281398 | B4002: =$K$3 -> 22.141753
A4003: -0.36975332 | B4003: =$K$3 -> 22.141753
A4004: -0.36975332 | B4004: 0
A4005: -0.36975332 | B4005: =$K$4 -> 19.974029
A4006: 6.0886331 | B4006: =$K$4 -> 19.974029
A4007: 6.0886331 | B4007: 0
A4008: 6.0886331 | B4008: =$K$5 -> 26.167527
A4009: 12.54702 | B4009: =$K$5 -> 26.167527
A4010: 12.54702 | B4010: 0
A4011: 12.54702 | B4011: =$K$6 -> 26.941714
A4012: 19.005406 | B4012: =$K$6 -> 26.941714
A4013: 19.005406 | B4013: 0
A4014: 19.005406 | B4014: =$K$7 -> 22.296591
A4015: 25.463793 | B4015: =$K$7 -> 22.296591
A4016: 25.463793 | B4016: 0
A4017: 25.463793 | B4017: =$K$8 -> 16.877281
A4018: 31.922179 | B4018: =$K$8 -> 16.877281
A4019: 31.922179 | B4019: 0
A4020: 31.922179 | B4020: =$K$9 -> 10.683783
A4021: 38.380565 | B4021: =$K$9 -> 10.683783
A4022: 38.380565 | B4022: 0
A4023: 38.380565 | B4023: =$K$10 -> 5.7289851
A4024: 44.838952 | B4024: =$K$10 -> 5.7289851
A4025: 44.838952 | B4025: 0
A4026: 44.838952 | B4026: =$K$11 -> 2.6322364
A4027: 51.297338 | B4027: =$K$11 -> 2.6322364
...

Sheet Company Data & Beta 
A1: F370 SU 2025 I-core Case Finance Raw Data for Company and Project beta
F2: These five projects comprise all of the company's business lines over the past five years.
A4: Past Security Returns (Percent) | F4: Monthly Gross Margin data for Recent Projects | N4: GM-to-Return Percentages
A5: Year | B5: Month | C5: Historic S&P 500 Mthly Return % | D5: Company Mthly Return % | E5: Historic 1 yr T-Bill % | F5: Project P | G5: Project Q | H5: Project R | I5: Project S | J5: Project T | K5: Tax Rate (see case) | L5: Debt to Equity (see case) | M5: Sum of Gross Margins | N5: P | O5: Q | P5: R | Q5: S | R5: T | S5: All
A6: 2020 | B6: Jan | C6: 0.10011 | D6: 0.4 | E6: 0.0222 | F6: 714457.65 | G6: 773731.5 | H6: 913232.49 | I6: 116227.2 | J6: 221553.95 | K6: 0.218 | L6: 0.185 | M6: =SUM(F6:J6) -> 2739202.8
B7: Feb | C7: -0.04543 | D7: -0.05 | E7: 0.0252 | F7: 879240.34 | G7: 752901.08 | H7: 1076028.6 | I7: 173700.86 | J7: 331111.05 | K7: 0.218 | L7: 0.185 | M7: =SUM(F7:J7) -> 3212981.9 | N7: =(F7-F6)/F6 -> 0.23064024 | O7: =(G7-G6)/G6 -> -0.026922019 | P7: =(H7-H6)/H6 -> 0.1782636 | Q7: =(I7-I6)/I6 -> 0.49449402 | R7: =(J7-J6)/J6 -> 0.49449402 | S7: =(M7-M6)/M6 -> 0.17296242
B8: Mar | C8: 0.06711 | D8: 0.089 | E8: 0.0282 | F8: 855569.41 | G8: 745813.39 | H8: 1061051.4 | I8: 162214.96 | J8: 309216.47 | K8: 0.218 | L8: 0.185 | M8: =SUM(F8:J8) -> 3133865.6 | N8: =(F8-F7)/F7 -> -0.026922019 | O8: =(G8-G7)/G7 -> -0.0094138389 | P8: =(H8-H7)/H7 -> -0.013918946 | Q8: =(I8-I7)/I7 -> -0.066124595 | R8: =(J8-J7)/J7 -> -0.066124595 | S8: =(M8-M7)/M7 -> -0.024623942
B9: Apr | C9: 0.08282 | D9: 0.09 | E9: 0.0312 | F9: 847515.22 | G9: 822354.34 | H9: 972641.77 | I9: 126258.94 | J9: 240676.58 | K9: 0.218 | L9: 0.185 | M9: =SUM(F9:J9) -> 3009446.9 | N9: =(F9-F8)/F8 -> -0.0094138389 | O9: =(G9-G8)/G8 -> 0.10262748 | P9: =(H9-H8)/H8 -> -0.083322675 | Q9: =(I9-I8)/I8 -> -0.22165664 | R9: =(J9-J8)/J8 -> -0.22165664 | S9: =(M9-M8)/M8 -> -0.03970138
B10: May | C10: -0.07336 | D10: -0.11 | E10: 0.0342 | F10: 934493.57 | G10: 732477.27 | H10: 1226377.7 | I10: 223556.55 | J10: 426146.69 | K10: 0.218 | L10: 0.185 | M10: =SUM(F10:J10) -> 3543051.8 | N10: =(F10-F9)/F9 -> 0.10262748 | O10: =(G10-G9)/G9 -> -0.1092924 | P10: =(H10-H9)/H9 -> 0.26087293 | Q10: =(I10-I9)/I9 -> 0.77061964 | R10: =(J10-J9)/J9 -> 0.77061964 | S10: =(M10-M9)/M9 -> 0.17730996
B11: Jun | C11: 0.26562 | D11: 0.44 | E11: 0.03 | F11: 832360.53 | G11: 748417.38 | H11: 992593.76 | I11: 157258.56 | J11: 299768.52 | K11: 0.218 | L11: 0.185 | M11: =SUM(F11:J11) -> 3030398.8 | N11: =(F11-F10)/F10 -> -0.1092924 | O11: =(G11-G10)/G10 -> 0.021761928 | P11: =(H11-H10)/H10 -> -0.19062963 | Q11: =(I11-I10)/I10 -> -0.29656025 | R11: =(J11-J10)/J10 -> -0.29656025 | S11: =(M11-M10)/M10 -> -0.1446925
B12: Jul | C12: -0.06657 | D12: -0.08 | E12: 0.0342 | F12: 850474.3 | G12: 613994.14 | H12: 1019811.6 | I12: 145252.6 | J12: 276882.57 | K12: 0.218 | L12: 0.185 | M12: =SUM(F12:J12) -> 2906415.2 | N12: =(F12-F11)/F11 -> 0.021761928 | O12: =(G12-G11)/G11 -> -0.17960999 | P12: =(H12-H11)/H11 -> 0.02742094 | Q12: =(I12-I11)/I11 -> -0.07634541 | R12: =(J12-J11)/J11 -> -0.07634541 | S12: =(M12-M11)/M11 -> -0.040913275
B13: Aug | C13: 0.13874 | D13: 0.19748 | E13: 0.0341 | F13: 697720.62 | G13: 703527.49 | H13: 890771.23 | I13: 117497.95 | J13: 223976.26 | K13: 0.218 | L13: 0.185 | M13: =SUM(F13:J13) -> 2633493.6 | N13: =(F13-F12)/F12 -> -0.17960999 | O13: =(G13-G12)/G12 -> 0.14582117 | P13: =(H13-H12)/H12 -> -0.12653354 | Q13: =(I13-I12)/I12 -> -0.19107849 | R13: =(J13-J12)/J12 -> -0.19107849 | S13: =(M13-M12)/M12 -> -0.093903191
B14: Sep | C14: -0.01728 | D14: -0.48918 | E14: 0.0348 | F14: 799463.06 | G14: 706376.37 | H14: 961304.65 | I14: 147679.37 | J14: 281508.51 | K14: 0.218 | L14: 0.185 | M14: =SUM(F14:J14) -> 2896332 | N14: =(F14-F13)/F13 -> 0.14582117 | O14: =(G14-G13)/G13 -> 0.0040494284 | P14: =(H14-H13)/H13 -> 0.079182415 | Q14: =(I14-I13)/I13 -> 0.25686761 | R14: =(J14-J13)/J13 -> 0.25686761 | S14: =(M14-M13)/M13 -> 0.09980598
B15: Oct | C15: 0.3788 | D15: 0.4 | E15: 0.0286 | F15: 802700.42 | G15: 792008.87 | H15: 998111.94 | I15: 142145.92 | J15: 270960.58 | K15: 0.218 | L15: 0.185 | M15: =SUM(F15:J15) -> 3005927.7 | N15: =(F15-F14)/F14 -> 0.0040494284 | O15: =(G15-G14)/G14 -> 0.12122786 | P15: =(H15-H14)/H14 -> 0.038288887 | Q15: =(I15-I14)/I14 -> -0.037469318 | R15: =(J15-J14)/J14 -> -0.037469318 | S15: =(M15-M14)/M14 -> 0.037839506
B16: Nov | C16: 0.10543 | D16: -0.001 | E16: 0.0248 | F16: 900010.08 | G16: 794112.16 | H16: 1216855.3 | I16: 228854.83 | J16: 436246.33 | K16: 0.218 | L16: 0.185 | M16: =SUM(F16:J16) -> 3576078.7 | N16: =(F16-F15)/F15 -> 0.12122786 | O16: =(G16-G15)/G15 -> 0.0026556405 | P16: =(H16-H15)/H15 -> 0.21915719 | Q16: =(I16-I15)/I15 -> 0.60999926 | R16: =(J16-J15)/J15 -> 0.60999926 | S16: =(M16-M15)/M15 -> 0.18967555
B17: Dec | C17: 0.03413 | D17: 0.66472 | E17: 0.0242 | F17: 902400.18 | G17: 753634.82 | H17: 1069789.9 | I17: 195561.28 | J17: 372781.7 | K17: 0.218 | L17: 0.185 | M17: =SUM(F17:J17) -> 3294167.8 | N17: =(F17-F16)/F16 -> 0.0026556405 | O17: =(G17-G16)/G16 -> -0.050971819 | P17: =(H17-H16)/H16 -> -0.12085699 | Q17: =(I17-I16)/I16 -> -0.14547889 | R17: =(J17-J16)/J16 -> -0.14547889 | S17: =(M17-M16)/M16 -> -0.078832407
A18: 2021 | B18: Jan | C18: 0.25304 | D18: 0.1 | E18: 0.0266 | F18: 856403.2 | G18: 679129.07 | H18: 1099295.6 | I18: 175156.36 | J18: 333885.54 | K18: 0.218 | L18: 0.185 | M18: =SUM(F18:J18) -> 3143869.7 | N18: =(F18-F17)/F17 -> -0.050971819 | O18: =(G18-G17)/G17 -> -0.098861873 | P18: =(H18-H17)/H17 -> 0.027580844 | Q18: =(I18-I17)/I17 -> -0.10434031 | R18: =(J18-J17)/J17 -> -0.10434031 | S18: =(M18-M17)/M17 -> -0.045625515
B19: Feb | C19: 0.14988 | D19: 0.7 | E19: 0.0277 | F19: 793394.9 | G19: 583213.39 | H19: 944888.63 | I19: 148120.95 | J19: 282350.26 | K19: 0.218 | L19: 0.185 | M19: =SUM(F19:J19) -> 2751968.1 | N19: =(F19-F18)/F18 -> -0.073573173 | O19: =(G19-G18)/G18 -> -0.14123335 | P19: =(H19-H18)/H18 -> -0.1404599 | Q19: =(I19-I18)/I18 -> -0.15435015 | R19: =(J19-J18)/J18 -> -0.15435015 | S19: =(M19-M18)/M18 -> -0.12465581
B20: Mar | C20: 0.29724 | D20: 0.22376 | E20: 0.0333 | F20: 807945.93 | G20: 678579.54 | H20: 1012788.4 | I20: 151791.12 | J20: 289346.41 | K20: 0.218 | L20: 0.185 | M20: =SUM(F20:J20) -> 2940451.4 | N20: =(F20-F19)/F19 -> 0.018340211 | O20: =(G20-G19)/G19 -> 0.16351844 | P20: =(H20-H19)/H19 -> 0.071860064 | Q20: =(I20-I19)/I19 -> 0.024778256 | R20: =(J20-J19)/J19 -> 0.024778256 | S20: =(M20-M19)/M19 -> 0.06849035
B21: Apr | C21: -0.0805 | D21: -0.03 | E21: 0.0258 | F21: 868835.62 | G21: 730536.58 | H21: 1127044.1 | I21: 219656.87 | J21: 418713.05 | K21: 0.218 | L21: 0.21 | M21: =SUM(F21:J21) -> 3364786.2 | N21: =(F21-F20)/F20 -> 0.075363572 | O21: =(G21-G20)/G20 -> 0.076567361 | P21: =(H21-H20)/H20 -> 0.11281298 | Q21: =(I21-I20)/I20 -> 0.44709954 | R21: =(J21-J20)/J20 -> 0.44709954 | S21: =(M21-M20)/M20 -> 0.14430941
B22: May | C22: -0.03644 | D22: -0.05 | E22: 0.0324 | F22: 884359.93 | G22: 626677.91 | H22: 1052702.3 | I22: 148028.52 | J22: 282174.08 | K22: 0.218 | L22: 0.21 | M22: =SUM(F22:J22) -> 2993942.8 | N22: =(F22-F21)/F21 -> 0.017867944 | O22: =(G22-G21)/G21 -> -0.14216766 | P22: =(H22-H21)/H21 -> -0.065961686 | Q22: =(I22-I21)/I21 -> -0.32609199 | R22: =(J22-J21)/J21 -> -0.32609199 | S22: =(M22-M21)/M21 -> -0.11021307
B23: Jun | C23: -0.18032 | D23: -0.3 | E23: 0.0328344 | F23: 882023.42 | G23: 814652.18 | H23: 1245132.7 | I23: 217094.53 | J23: 413828.68 | K23: 0.218 | L23: 0.21 | M23: =SUM(F23:J23) -> 3572731.5 | N23: =(F23-F22)/F22 -> -0.0026420381 | O23: =(G23-G22)/G22 -> 0.29995356 | P23: =(H23-H22)/H22 -> 0.18279657 | Q23: =(I23-I22)/I22 -> 0.46657229 | R23: =(J23-J22)/J22 -> 0.46657229 | S23: =(M23-M22)/M22 -> 0.19331991
B24: Jul | C24: 0.31828 | D24: 0.21 | E24: 0.0332688 | F24: 828770.73 | G24: 709689.71 | H24: 1074706.9 | I24: 157859.34 | J24: 300913.72 | K24: 0.218 | L24: 0.21 | M24: =SUM(F24:J24) -> 3071940.4 | N24: =(F24-F23)/F23 -> -0.060375588 | O24: =(G24-G23)/G23 -> -0.12884328 | P24: =(H24-H23)/H23 -> -0.13687361 | Q24: =(I24-I23)/I23 -> -0.27285436 | R24: =(J24-J23)/J23 -> -0.27285436 | S24: =(M24-M23)/M23 -> -0.14017037
B25: Aug | C25: 0.04817 | D25: -0.001 | E25: 0.0337032 | F25: 915338.35 | G25: 778078.86 | H25: 1100990.1 | I25: 178909.95 | J25: 341040.7 | K25: 0.218 | L25: 0.21 | M25: =SUM(F25:J25) -> 3314358 | N25: =(F25-F24)/F24 -> 0.10445303 | O25: =(G25-G24)/G24 -> 0.096364857 | P25: =(H25-H24)/H24 -> 0.024456195 | Q25: =(I25-I24)/I24 -> 0.13335043 | R25: =(J25-J24)/J24 -> 0.13335043 | S25: =(M25-M24)/M24 -> 0.078913507
B26: Sep | C26: -0.09813 | D26: -0.05 | E26: 0.0341376 | F26: 831843.38 | G26: 619786.21 | H26: 1009231.7 | I26: 180038.32 | J26: 343191.6 | K26: 0.218 | L26: 0.21 | M26: =SUM(F26:J26) -> 2984091.2 | N26: =(F26-F25)/F25 -> -0.091217596 | O26: =(G26-G25)/G25 -> -0.20344037 | P26: =(H26-H25)/H25 -> -0.083341743 | Q26: =(I26-I25)/I25 -> 0.0063068918 | R26: =(J26-J25)/J25 -> 0.0063068918 | S26: =(M26-M25)/M25 -> -0.099647287
B27: Oct | C27: 0.21238 | D27: 0.21 | E27: 0.034572 | F27: 908453.31 | G27: 672787.33 | H27: 1110952 | I27: 185893.84 | J27: 354353.48 | K27: 0.218 | L27: 0.21 | M27: =SUM(F27:J27) -> 3232440 | N27: =(F27-F26)/F26 -> 0.092096575 | O27: =(G27-G26)/G26 -> 0.085515168 | P27: =(H27-H26)/H26 -> 0.10078987 | Q27: =(I27-I26)/I26 -> 0.032523751 | R27: =(J27-J26)/J26 -> 0.032523751 | S27: =(M27-M26)/M26 -> 0.08322426
B28: Nov | C28: 0.00387 | D28: 0.002 | E28: 0.0350064 | F28: 875359.16 | G28: 627503.16 | H28: 1059187.4 | I28: 165426.27 | J28: 315337.91 | K28: 0.255 | L28: 0.21 | M28: =SUM(F28:J28) -> 3042813.9 | N28: =(F28-F27)/F27 -> -0.036429113 | O28: =(G28-G27)/G27 -> -0.0673083 | P28: =(H28-H27)/H27 -> -0.046594881 | Q28: =(I28-I27)/I27 -> -0.11010355 | R28: =(J28-J27)/J27 -> -0.11010355 | S28: =(M28-M27)/M27 -> -0.05866347
B29: Dec | C29: 0.02125 | D29: 0.35434 | E29: 0.0354408 | F29: 904506.38 | G29: 669967.41 | H29: 1080636.9 | I29: 195063.81 | J29: 371833.41 | K29: 0.255 | L29: 0.21 | M29: =SUM(F29:J29) -> 3222007.9 | N29: =(F29-F28)/F28 -> 0.033297439 | O29: =(G29-G28)/G28 -> 0.067671773 | P29: =(H29-H28)/H28 -> 0.020250926 | Q29: =(I29-I28)/I28 -> 0.17915862 | R29: =(J29-J28)/J28 -> 0.17915862 | S29: =(M29-M28)/M28 -> 0.058890897
A30: 2022 | B30: Jan | C30: 0.21495 | D30: -0.7348 | E30: 0.0358752 | F30: 876133.72 | G30: 831165.22 | H30: 1223187.5 | I30: 207803.43 | J30: 396117.86 | K30: 0.255 | L30: 0.21 | M30: =SUM(F30:J30) -> 3534407.7 | N30: =(F30-F29)/F29 -> -0.031368115 | O30: =(G30-G29)/G29 -> 0.24060544 | P30: =(H30-H29)/H29 -> 0.13191347 | Q30: =(I30-I29)/I29 -> 0.065310038 | R30: =(J30-J29)/J29 -> 0.065310038 | S30: =(M30-M29)/M29 -> 0.096958108
B31: Feb | C31: 0.18989 | D31: 0.5 | E31: 0.0363096 | F31: 790009.87 | G31: 629596.97 | H31: 959086.54 | I31: 152202.38 | J31: 290130.35 | K31: 0.255 | L31: 0.21 | M31: =SUM(F31:J31) -> 2821026.1 | N31: =(F31-F30)/F30 -> -0.098299892 | O31: =(G31-G30)/G30 -> -0.24251285 | P31: =(H31-H30)/H30 -> -0.21591205 | Q31: =(I31-I30)/I30 -> -0.26756559 | R31: =(J31-J30)/J30 -> -0.26756559 | S31: =(M31-M30)/M30 -> -0.20183907
B32: Mar | C32: -0.051856 | D32: -0.04076 | E32: 0.036744 | F32: 823031.33 | G32: 755853.09 | H32: 1124699.3 | I32: 199665.7 | J32: 380605.61 | K32: 0.255 | L32: 0.21 | M32: =SUM(F32:J32) -> 3283855.1 | N32: =(F32-F31)/F31 -> 0.041798787 | O32: =(G32-G31)/G31 -> 0.20053483 | P32: =(H32-H31)/H31 -> 0.17267765 | Q32: =(I32-I31)/I31 -> 0.31184349 | R32: =(J32-J31)/J31 -> 0.31184349 | S32: =(M32-M31)/M31 -> 0.16406405
B33: Apr | C33: 0.070768 | D33: 0.15474 | E33: 0.0371784 | F33: 893561.57 | G33: 724194.05 | H33: 1129107.3 | I33: 208458.24 | J33: 397366.06 | K33: 0.255 | L33: 0.21 | M33: =SUM(F33:J33) -> 3352687.2 | N33: =(F33-F32)/F32 -> 0.085695698 | O33: =(G33-G32)/G32 -> -0.041885178 | P33: =(H33-H32)/H32 -> 0.0039192191 | Q33: =(I33-I32)/I32 -> 0.044036264 | R33: =(J33-J32)/J32 -> 0.044036264 | S33: =(M33-M32)/M32 -> 0.020960769
B34: May | C34: 0.120628 | D34: 0.50522 | E34: 0.0376128 | F34: 904808.01 | G34: 769531.95 | H34: 1085163.8 | I34: 559854.55 | J34: 345556.61 | K34: 0.255 | L34: 0.21 | M34: =SUM(F34:J34) -> 3664915 | N34: =(F34-F33)/F33 -> 0.01258608 | O34: =(G34-G33)/G33 -> 0.062604623 | P34: =(H34-H33)/H33 -> -0.038918754 | Q34: =(I34-I33)/I33 -> 1.6856917 | R34: =(J34-J33)/J33 -> -0.13038217 | S34: =(M34-M33)/M33 -> 0.093127609
B35: Jun | C35: 0.093617 | D35: 0.86078 | E35: 0.0380472 | F35: 859555.33 | G35: 645659.74 | H35: 1084469.5 | I35: 520462.47 | J35: 264401.8 | K35: 0.255 | L35: 0.21 | M35: =SUM(F35:J35) -> 3374548.8 | N35: =(F35-F34)/F34 -> -0.050013565 | O35: =(G35-G34)/G34 -> -0.16097084 | P35: =(H35-H34)/H34 -> -0.00063988021 | Q35: =(I35-I34)/I34 -> -0.070361271 | R35: =(J35-J34)/J34 -> -0.23485244 | S35: =(M35-M34)/M34 -> -0.079228617
B36: Jul | C36: 0.118987 | D36: 0.4216 | E36: 0.0384816 | F36: 914285.79 | G36: 812001.7 | H36: 1229824.1 | I36: 572511.34 | J36: 427921.78 | K36: 0.255 | L36: 0.21 | M36: =SUM(F36:J36) -> 3956544.7 | N36: =(F36-F35)/F35 -> 0.063672986 | O36: =(G36-G35)/G35 -> 0.25763098 | P36: =(H36-H35)/H35 -> 0.13403295 | Q36: =(I36-I35)/I35 -> 0.10000505 | R36: =(J36-J35)/J35 -> 0.61845258 | S36: =(M36-M35)/M35 -> 0.17246629
B37: Aug | C37: -0.12 | D37: -0.38572 | E37: 0.0358752 | F37: 890423.77 | G37: 739180.44 | H37: 1050960.9 | I37: 535242.45 | J37: 341535.28 | K37: 0.255 | L37: 0.21 | M37: =SUM(F37:J37) -> 3557342.8 | N37: =(F37-F36)/F36 -> -0.026099084 | O37: =(G37-G36)/G36 -> -0.089681166 | P37: =(H37-H36)/H36 -> -0.14543807 | Q37: =(I37-I36)/I36 -> -0.065097222 | R37: =(J37-J36)/J36 -> -0.20187449 | S37: =(M37-M36)/M36 -> -0.1008966
B38: Sep | C38: 0.089187 | D38: 0.14072 | E38: 0.034572 | F38: 836435.04 | G38: 656897.68 | H38: 1063273.5 | I38: 439978.92 | J38: 289363.58 | K38: 0.255 | L38: 0.21 | M38: =SUM(F38:J38) -> 3285948.7 | N38: =(F38-F37)/F37 -> -0.060632625 | O38: =(G38-G37)/G37 -> -0.1113162 | P38: =(H38-H37)/H37 -> 0.011715621 | Q38: =(I38-I37)/I37 -> -0.17798202 | R38: =(J38-J37)/J37 -> -0.15275641 | S38: =(M38-M37)/M37 -> -0.07629123
B39: Oct | C39: 0.090925 | D39: 0.3759 | E39: 0.0350064 | F39: 860546.64 | G39: 643303.14 | H39: 979641.51 | I39: 447498.45 | J39: 266878.71 | K39: 0.255 | L39: 0.222 | M39: =SUM(F39:J39) -> 3197868.5 | N39: =(F39-F38)/F38 -> 0.028826635 | O39: =(G39-G38)/G38 -> -0.020695069 | P39: =(H39-H38)/H38 -> -0.078655222 | Q39: =(I39-I38)/I38 -> 0.017090679 | R39: =(J39-J38)/J38 -> -0.077704559 | S39: =(M39-M38)/M38 -> -0.026805129
B40: Nov | C40: 0.110295 | D40: 0.12 | E40: 0.0354408 | F40: 820832.5 | G40: 687936.01 | H40: 1060609.1 | I40: 546865.23 | J40: 347597.36 | K40: 0.255 | L40: 0.222 | M40: =SUM(F40:J40) -> 3463840.2 | N40: =(F40-F39)/F39 -> -0.046149906 | O40: =(G40-G39)/G39 -> 0.06938078 | P40: =(H40-H39)/H39 -> 0.082650258 | Q40: =(I40-I39)/I39 -> 0.22204943 | R40: =(J40-J39)/J39 -> 0.30245445 | S40: =(M40-M39)/M39 -> 0.083171582
B41: Dec | C41: 0.107789 | D41: 0.108 | E41: 0.0358752 | F41: 896170.29 | G41: 660663.67 | H41: 1090435.9 | I41: 508751.89 | J41: 306494.35 | K41: 0.255 | L41: 0.222 | M41: =SUM(F41:J41) -> 3462516.1 | N41: =(F41-F40)/F40 -> 0.091782174 | O41: =(G41-G40)/G40 -> -0.039643715 | P41: =(H41-H40)/H40 -> 0.028122294 | Q41: =(I41-I40)/I40 -> -0.069694201 | R41: =(J41-J40)/J40 -> -0.11824893 | S41: =(M41-M40)/M40 -> -0.00038227477
...

Sheet Cash Flow Assumptions
A1: Project Cash Flows
A2: Unit Assumptions | B2: 0 | C2: 1 | D2: 2 | E2: 3 | F2: 4 | G2: 5 | H2: 6 | I2: 7 | J2: 8 | K2: 9 | L2: 10
A3: Unit quantity | C3: 100000 | D3: =C3*1.1 -> 110000 | E3: =D3*1.1 -> 121000 | F3: =E3*1.1 -> 133100 | G3: =F3*1.1 -> 146410 | H3: =G3*1.1 -> 161051 | I3: =H3*1.1 -> 177156.1 | J3: =I3*1.1 -> 194871.71 | K3: =J3*1.1 -> 214358.88 | L3: =K3*1.1 -> 235794.77
A4: Unit Selling Price (for retail) | C4: 75 | D4: 75 | E4: 75 | F4: 75 | G4: 75 | H4: 75 | I4: 75 | J4: 75 | K4: 75 | L4: 75
A5: Net Unit Selling Price (revenue) (net channel costs and incentives) | C5: 35 | D5: 35 | E5: 35 | F5: 35 | G5: 35 | H5: 35 | I5: 35 | J5: 35 | K5: 35 | L5: 35
A6: Material Unit Variable Cost | C6: 6.19 | D6: =C6*1.015 -> 6.28285 | E6: =D6*1.015 -> 6.3770927 | F6: =E6*1.015 -> 6.4727491 | G6: =F6*1.015 -> 6.5698404 | H6: =G6*1.015 -> 6.668388 | I6: =H6*1.015 -> 6.7684138 | J6: =I6*1.015 -> 6.86994 | K6: =J6*1.015 -> 6.9729891 | L6: =K6*1.015 -> 7.0775839
A7: Overhead Unit Variable Cost | C7: =4.08 -> 4.08 | D7: =4.08 -> 4.08 | E7: =4.08 -> 4.08 | F7: =1.12 -> 1.12 | G7: =1.12 -> 1.12 | H7: =1.12 -> 1.12 | I7: =1.12 -> 1.12 | J7: =1.12 -> 1.12 | K7: =1.12 -> 1.12 | L7: =1.12 -> 1.12
A8: Unit Fixed Cost | C8: =(70000*4)/C3 -> 2.8 | D8: =(70000*4)/D3 -> 2.5454545 | E8: =(70000*4)/E3 -> 2.3140496 | F8: =((70000*4)+50000)/F3 -> 2.4793388 | G8: =((70000*4)+50000)/G3 -> 2.2539444 | H8: =((70000*4)+50000)/H3 -> 2.0490404 | I8: =((70000*4)+50000)/I3 -> 1.862764 | J8: =((70000*4)+50000)/J3 -> 1.6934218 | K8: =((70000*4)+50000)/K3 -> 1.5394744 | L8: =((70000*4)+50000)/L3 -> 1.3995221
M9: Depreciable Assets
A10: Project Assumptions
B11: 0 | C11: 1 | D11: 2 | E11: 3 | F11: 4 | G11: 5 | H11: 6 | I11: 7 | J11: 8 | K11: 9 | L11: 10 | M11: Deprec Asset Class | N11: ED | O11: Recovery Period (SL) | P11: Annual Depr | R11: MV5 | S11: BV5 | T11: NSV5
A12: Units Sold | C12: =C3 -> 100000 | D12: =D3 -> 110000 | E12: =E3 -> 121000 | F12: =F3 -> 133100 | G12: =G3 -> 146410 | H12: =H3 -> 161051 | I12: =I3 -> 177156.1 | J12: =J3 -> 194871.71 | ... L12: =L3 -> 235794.77 | M12: A | N12: 150000 | O12: 5 | P12: =N12/O12 -> 30000 | R12: =0 -> 0 | S12: =N12-(O12*P12)+U12 -> 0 | T12: =S12-(S12*'Company Data & Beta '!$B$70) -> 0
A13: Revenue | C13: =C12*C5 -> 3500000 | D13: =D12*D5 -> 3850000 | E13: =E12*E5 -> 4235000 | F13: =F12*F5 -> 4658500 | G13: =G12*G5 -> 5124350 | H13: =H12*H5 -> 5636785 | I13: =I12*I5 -> 6200463.5 | J13: =J12*J5 -> 6820509.9 | ... L13: =L12*L5 -> 8252816.9 | M13: B | N13: 110000 | O13: 5 | P13: =N13/O13 -> 22000 | R13: =0 -> 0 | S13: =N13-(O13*P13)+U13 -> 0 | T13: =S13-(S13*'Company Data & Beta '!$B$70) -> 0
A14: Synergies or Erosion impacts | C14: =C12*8*0.55 -> 440000 | D14: =D12*8*0.55 -> 484000 | E14: =E12*8*0.55 -> 532400 | F14: =F12*8*0.55 -> 585640 | G14: =G12*8*0.55 -> 644204 | H14: =H12*8*0.55 -> 708624.4 | I14: =I12*8*0.55 -> 779486.84 | J14: =J12*8*0.55 -> 857435.52 | ... L14: =L12*8*0.55 -> 1037497 | M14: C | N14: 40000 | O14: 5 | P14: =N14/O14 -> 8000 | R14: =0 -> 0 | S14: =N14-(O14*P14)+U14 -> 0 | T14: =S14-(S14*'Company Data & Beta '!$B$70) -> 0
A15: Variable Expenses | C15: =(C12*C7)+(C12*C6) -> 1027000 | D15: =(D12*D7)+(D12*D6) -> 1139913.5 | E15: =(E12*E7)+(E12*E6) -> 1265308.2 | F15: =(F12*F7)+(F12*F6) -> 1010594.9 | G15: =(G12*G7)+(G12*G6) -> 1125869.5 | H15: =(H12*H7)+(H12*H6) -> 1254327.7 | I15: =(I12*I7)+(I12*I6) -> 1397480.6 | J15: =(J12*J7)+(J12*J6) -> 1557013.3 | ... L15: =(L12*L7)+(L12*L6) -> 1932947.4 | M15: D | N15: =100000-U15 -> 100000 | O15: 5 | P15: =(70000-30000)/5 -> 8000 | R15: =0 -> 0 | S15: 30000 | T15: =S15-(S15*'Company Data & Beta '!$B$70) -> 23142
A16: Fixed Expenses | C16: =C8*C3 -> 280000 | D16: =D8*D3 -> 280000 | E16: =E8*E3 -> 280000 | F16: =F8*F3 -> 330000 | G16: =G8*G3 -> 330000 | H16: =H8*H3 -> 330000 | I16: =I8*I3 -> 330000 | J16: =J8*J3 -> 330000 | ... L16: =L8*L3 -> 330000 | M16: E | N16: =750000 -> 750000 | O16: 5 | P16: =N16/O16 -> 150000 | R16: =0 -> 0 | S16: =N16-(P16*2) -> 450000 | T16: =0 -> 0
A17: Commission Expenses | C17: =(0.01*C13) -> 35000 | D17: =(0.01*D13) -> 38500 | E17: =(0.01*E13) -> 42350 | F17: =(0.01*F13) -> 46585 | G17: =(0.01*G13) -> 51243.5 | H17: =(0.5%*H13) -> 28183.925 | I17: =(0.5%*I13) -> 31002.318 | J17: =(0.5%*J13) -> 34102.549 | K17: =(0.5%*K13) -> 37512.804 | L17: =0.5%*L13 -> 41264.085 | M17: totals | N17: =SUM(N12:N16) -> 1150000 | P17: =SUM(P12:P16) -> 218000 | R17: =SUM(R12:R15) -> 0 | S17: =SUM(S12:S16) -> 480000 | T17: =SUM(T12:T15) -> 23142
A18: Campaign Expenses | C18: =80000 -> 80000 | D18: =(13%*D13) -> 500500 | E18: =(13%*E13) -> 550550 | F18: =(13%*F13) -> 605605 | G18: =(13%*G13) -> 666165.5 | H18: =(13%*H13) -> 732782.05 | I18: =(13%*I13) -> 806060.26 | J18: =(13%*J13) -> 886666.28 | K18: =(13%*K13) -> 975332.91 | L18: =13%*L13 -> 1072866.2
A19: Depreciation Expense | C19: =SUM($P$12:$P$15) -> 68000 | D19: =SUM($P$12:$P$15) -> 68000 | E19: =SUM($P$12:$P$15) -> 68000 | F19: =SUM($P$12:$P$16) -> 218000 | G19: =SUM($P$12:$P$16) -> 218000 | H19: =SUM($P$12:$P$16) -> 218000 | I19: =SUM($P$12:$P$16) -> 218000 | J19: =SUM($P$12:$P$16) -> 218000 | K19: =SUM($P$12:$P$16) -> 218000 | L19: =SUM($P$12:$P$16) -> 218000
A20: Net working Capital | B20: 150000 | C20: =0.5*C12 -> 50000 | D20: =0.5*D12 -> 55000 | E20: =0.5*E12 -> 60500 | F20: =0.5*F12 -> 66550 | G20: =0.5*G12 -> 73205 | H20: =0.5*H12 -> 80525.5 | I20: =0.5*I12 -> 88578.05 | J20: =0.5*J12 -> 97435.855 | K20: =0.5*K12 -> 107179.44 | L20: 0 | M20: Assume any loss on salvage of machinery result in an immediate tax deduction which adds to total cash flows in the same year of disposal
A21: Capital Equipment | B21: =N12+N13+N14+N15 -> 400000 | F21: =N16 -> 750000 | G21: =N12+N13+N14+N15 -> 400000 | K21: =F21 -> 750000
A22: Net Salvage Value\ | G22: =L22 -> 23142 | L22: =T15 -> 23142
A23: Taxes | C23: =(C13-SUM(C14:C19))*'Company Data & Beta '!$B$70 -> 358902 | D23: =(D13-SUM(D14:D19))*'Company Data & Beta '!$B$70 -> 306115.17 | E23: =(E13-SUM(E14:E19))*'Company Data & Beta '!$B$70 -> 342075.16 | F23: =(F13-SUM(F14:F19))*'Company Data & Beta '!$B$70 -> 425670.37 | G23: =(G13-SUM(G14:G19))*'Company Data & Beta '!$B$70 -> 477515.1 | H23: =(H13-SUM(H14:H19))*'Company Data & Beta '!$B$70 -> 540608.59 | I23: =(I13-SUM(I14:I19))*'Company Data & Beta '!$B$70 -> 603145.89 | J23: =(J13-SUM(J14:J19))*'Company Data & Beta '!$B$70 -> 671465 | ... L23: =(L13-SUM(L14:L19))*'Company Data & Beta '!$B$70 -> 827587.38
A25: Project Decision Metrics | F25: Benchmark CAPM Returns | M25: Side Effects
M26: Year | N26: 1 | O26: 2 | P26: 3 | Q26: 4 | R26: 5 | S26: 6 | T26: 7 | U26: 8 | V26: 9 | W26: 10
A27: Project b | B27: ='Company Data & Beta '!B81 -> 0.91707152 | G27: Risk Free Rate | H27: ='Company Data & Beta '!I67 -> 0.036356131 | M27: New Units Sold | N27: =C3 -> 100000 | O27: =D3 -> 110000 | P27: =E3 -> 121000 | Q27: =F3 -> 133100 | R27: =G3 -> 146410 | S27: =H3 -> 161051 | T27: =I3 -> 177156.1 | U27: =J3 -> 194871.71 | ... W27: =L3 -> 235794.77
A28: Project IRR | B28: ='Baseline DCF NPV analysis'!B22 -> 1.803997 | G28: Equity Market Risk Premium | H28: ='Company Data & Beta '!D70 -> 0.03674624 | M28: Old Units Cannibalized | N28: =8*N27 -> 800000 | O28: =8*O27 -> 880000 | P28: =8*P27 -> 968000 | Q28: =8*Q27 -> 1064800 | R28: =8*R27 -> 1171280 | S28: =8*S27 -> 1288408 | T28: =8*T27 -> 1417248.8 | U28: =8*U27 -> 1558973.7 | ... W28: =8*W27 -> 1886358.2
A29: Project Cost of Capital | B29: ='Company Data & Beta '!I78 -> 0.082055062 | G29: Possible Liquidity Premium | H29: 0.012 | M29: Loss of Revenue | N29: =N28*0.55 -> 440000 | O29: =O28*0.55 -> 484000 | P29: =P28*0.55 -> 532400 | Q29: =Q28*0.55 -> 585640 | R29: =R28*0.55 -> 644204 | S29: =S28*0.55 -> 708624.4 | T29: =T28*0.55 -> 779486.84 | U29: =U28*0.55 -> 857435.52 | ... W29: =W28*0.55 -> 1037497
A30: Project NPV | B30: ='Baseline DCF NPV analysis'!B21 -> 10323311 | M30: New Revenue | N30: =N27*35 -> 3500000 | O30: =O27*35 -> 3850000 | P30: =P27*35 -> 4235000 | Q30: =Q27*35 -> 4658500 | R30: =R27*35 -> 5124350 | S30: =S27*35 -> 5636785 | T30: =T27*35 -> 6200463.5 | U30: =U27*35 -> 6820509.9 | ... W30: =W27*35 -> 8252816.9
F31: Treasury Debt Data (All data assume semi-annual coupon payments) | X31: average
F32: Maturity | G32: Current Price | H32: Coupon Rate | I32: Face Value | M32: Net Cash Flow pre-tax | N32: =N30-N29 -> 3060000 | O32: =O30-O29 -> 3366000 | P32: =P30-P29 -> 3702600 | Q32: =Q30-Q29 -> 4072860 | R32: =R30-R29 -> 4480146 | S32: =S30-S29 -> 4928160.6 | T32: =T30-T29 -> 5420976.7 | U32: =U30-U29 -> 5963074.3 | ... W32: =W30-W29 -> 7215319.9 | X32: =AVERAGE(N32:W32) -> 4876851.9
F33: 1 year | G33: 965.05 | H33: 0 | I33: 1000
F34: 5 years | G34: 955.16 | H34: 0.027 | I34: 1000
F35: 10 years | G35: 955.43 | H35: 0.031 | I35: 1000

Sheet Baseline DCF NPV analysis
A2: Timepoint | B2: 0 | C2: 1 | D2: 2 | E2: 3 | F2: 4 | G2: 5 | H2: 6 | I2: 7 | J2: 8 | K2: 9 | L2: 10
A3: Revenue | B3: ='Cash Flow Assumptions'!B3*'Cash Flow Assumptions'!B5 -> 0 | C3: ='Cash Flow Assumptions'!C3*'Cash Flow Assumptions'!C5 -> 3500000 | D3: ='Cash Flow Assumptions'!D3*'Cash Flow Assumptions'!D5 -> 3850000 | E3: ='Cash Flow Assumptions'!E3*'Cash Flow Assumptions'!E5 -> 4235000 | F3: ='Cash Flow Assumptions'!F3*'Cash Flow Assumptions'!F5 -> 4658500 | G3: ='Cash Flow Assumptions'!G3*'Cash Flow Assumptions'!G5 -> 5124350 | H3: ='Cash Flow Assumptions'!H3*'Cash Flow Assumptions'!H5 -> 5636785 | I3: ='Cash Flow Assumptions'!I3*'Cash Flow Assumptions'!I5 -> 6200463.5 | ... L3: ='Cash Flow Assumptions'!L3*'Cash Flow Assumptions'!L5 -> 8252816.9
A4: Side Effects | B4: ='Cash Flow Assumptions'!B14 -> 0 | C4: ='Cash Flow Assumptions'!C14 -> 440000 | D4: ='Cash Flow Assumptions'!D14 -> 484000 | E4: ='Cash Flow Assumptions'!E14 -> 532400 | F4: ='Cash Flow Assumptions'!F14 -> 585640 | G4: ='Cash Flow Assumptions'!G14 -> 644204 | H4: ='Cash Flow Assumptions'!H14 -> 708624.4 | I4: ='Cash Flow Assumptions'!I14 -> 779486.84 | ... L4: ='Cash Flow Assumptions'!L14 -> 1037497
A5: Variable Expenses | B5: ='Cash Flow Assumptions'!B15 -> 0 | C5: ='Cash Flow Assumptions'!C15 -> 1027000 | D5: ='Cash Flow Assumptions'!D15 -> 1139913.5 | E5: ='Cash Flow Assumptions'!E15 -> 1265308.2 | F5: ='Cash Flow Assumptions'!F15 -> 1010594.9 | G5: ='Cash Flow Assumptions'!G15 -> 1125869.5 | H5: ='Cash Flow Assumptions'!H15 -> 1254327.7 | I5: ='Cash Flow Assumptions'!I15 -> 1397480.6 | ... L5: ='Cash Flow Assumptions'!L15 -> 1932947.4
A6: Fixed Expenses | B6: ='Cash Flow Assumptions'!B16 -> 0 | C6: ='Cash Flow Assumptions'!C16 -> 280000 | D6: ='Cash Flow Assumptions'!D16 -> 280000 | E6: ='Cash Flow Assumptions'!E16 -> 280000 | F6: ='Cash Flow Assumptions'!F16 -> 330000 | G6: ='Cash Flow Assumptions'!G16 -> 330000 | H6: ='Cash Flow Assumptions'!H16 -> 330000 | I6: ='Cash Flow Assumptions'!I16 -> 330000 | ... L6: ='Cash Flow Assumptions'!L16 -> 330000
A7: Commision Expense | B7: ='Cash Flow Assumptions'!B17 -> 0 | C7: ='Cash Flow Assumptions'!C17 -> 35000 | D7: ='Cash Flow Assumptions'!D17 -> 38500 | E7: ='Cash Flow Assumptions'!E17 -> 42350 | F7: ='Cash Flow Assumptions'!F17 -> 46585 | G7: ='Cash Flow Assumptions'!G17 -> 51243.5 | H7: ='Cash Flow Assumptions'!H17 -> 28183.925 | I7: ='Cash Flow Assumptions'!I17 -> 31002.318 | ... L7: ='Cash Flow Assumptions'!L17 -> 41264.085
A8: Immediate Expense | B8: 160000
A9: Campaign Expense | B9: 0 | C9: ='Cash Flow Assumptions'!C18 -> 80000 | D9: ='Cash Flow Assumptions'!D18 -> 500500 | E9: ='Cash Flow Assumptions'!E18 -> 550550 | F9: ='Cash Flow Assumptions'!F18 -> 605605 | G9: ='Cash Flow Assumptions'!G18 -> 666165.5 | H9: ='Cash Flow Assumptions'!H18 -> 732782.05 | I9: ='Cash Flow Assumptions'!I18 -> 806060.26 | J9: ='Cash Flow Assumptions'!J18 -> 886666.28 | ... L9: ='Cash Flow Assumptions'!L18 -> 1072866.2
A10: Remediation Expense | B10: 0 | C10: 100000 | D10: 100000 | E10: 100000 | F10: 100000 | G10: 100000 | H10: 100000 | I10: 100000 | J10: 100000 | K10: 100000
A11: Depreciation Expense | B11: ='Cash Flow Assumptions'!B19 -> 0 | C11: ='Cash Flow Assumptions'!C19 -> 68000 | D11: ='Cash Flow Assumptions'!D19 -> 68000 | E11: ='Cash Flow Assumptions'!E19 -> 68000 | F11: ='Cash Flow Assumptions'!F19 -> 218000 | G11: ='Cash Flow Assumptions'!G19 -> 218000 | H11: ='Cash Flow Assumptions'!H19 -> 218000 | I11: ='Cash Flow Assumptions'!I19 -> 218000 | ... L11: ='Cash Flow Assumptions'!L19 -> 218000
A12: Earnings Before Interest and Taxes (PBT or EBIT) | B12: =B3-SUM(B4:B11) -> -160000 | C12: =C3-SUM(C4:C11) -> 1470000 | D12: =D3-SUM(D4:D11) -> 1239086.5 | E12: =E3-SUM(E4:E11) -> 1396391.8 | F12: =F3-SUM(F4:F11) -> 1762075.1 | G12: =G3-SUM(G4:G11) -> 1988867.5 | H12: =H3-SUM(H4:H11) -> 2264867 | I12: =I3-SUM(I4:I11) -> 2538433.5 | ... L12: =L3-SUM(L4:L11) -> 3620242.2
A13: Taxes | B13: =B12*'Company Data & Beta '!$B$70 -> -36576 | C13: =C12*'Company Data & Beta '!$B$70 -> 336042 | D13: =D12*'Company Data & Beta '!$B$70 -> 283255.17 | E13: =E12*'Company Data & Beta '!$B$70 -> 319215.16 | F13: =F12*'Company Data & Beta '!$B$70 -> 402810.37 | G13: =G12*'Company Data & Beta '!$B$70 -> 454655.1 | H13: =H12*'Company Data & Beta '!$B$70 -> 517748.59 | I13: =I12*'Company Data & Beta '!$B$70 -> 580285.89 | ... L13: =L12*'Company Data & Beta '!$B$70 -> 827587.38
A14: Normal Operating Profit After Tax (NOPAT) | B14: =B12-B13 -> -123424 | C14: =C12-C13 -> 1133958 | D14: =D12-D13 -> 955831.33 | E14: =E12-E13 -> 1077176.6 | F14: =F12-F13 -> 1359264.7 | G14: =G12-G13 -> 1534212.4 | H14: =H12-H13 -> 1747118.4 | I14: =I12-I13 -> 1958147.6 | ... L14: =L12-L13 -> 2792654.9
